Workbook

Sheet Food Log
A1: Food | B1: Amount | C1: Date | D1: Kcal | E1: Protein
A2: Subway Single Fileto(15cm) | B2: 2 | C2: 46218 | D2: =IFERROR(_xlfn.XLOOKUP(A2,'Food Database'!A:A,'Food Database'!B:B)*B2,"") -> 800 | E2: =IFERROR(_xlfn.XLOOKUP(A2,'Food Database'!A:A,'Food Database'!C:C)*B2,"") -> 51.2
A3: Starbucks Grande Iced Protein Latte | B3: 1 | C3: 46218 | D3: =IFERROR(_xlfn.XLOOKUP(A3,'Food Database'!A:A,'Food Database'!B:B)*B3,"") -> 123 | E3: =IFERROR(_xlfn.XLOOKUP(A3,'Food Database'!A:A,'Food Database'!C:C)*B3,"") -> 21
A4: Tavuk Kanat | B4: 4 | C4: 46219 | D4: =IFERROR(_xlfn.XLOOKUP(A4,'Food Database'!A:A,'Food Database'!B:B)*B4,"") -> 360 | E4: =IFERROR(_xlfn.XLOOKUP(A4,'Food Database'!A:A,'Food Database'!C:C)*B4,"") -> 30
A5: Yağsız Çoban Salata | B5: N/A | C5: 46219 | D5: 30 | E5: 1.5
A6: Subway Winterberry Cookie | B6: 0.25 | C6: 46219 | D6: =IFERROR(_xlfn.XLOOKUP(A6,'Food Database'!A:A,'Food Database'!B:B)*B6,"") -> 50 | E6: =IFERROR(_xlfn.XLOOKUP(A6,'Food Database'!A:A,'Food Database'!C:C)*B6,"") -> 0.5
A7: Subway Double Fileto(15 cm) | B7: 1 | C7: 46219 | D7: =IFERROR(_xlfn.XLOOKUP(A7,'Food Database'!A:A,'Food Database'!B:B)*B7,"") -> 550 | E7: =IFERROR(_xlfn.XLOOKUP(A7,'Food Database'!A:A,'Food Database'!C:C)*B7,"") -> 47
A8: Büyük Salatalık | B8: 1 | C8: 46220 | D8: =IFERROR(_xlfn.XLOOKUP(A8,'Food Database'!A:A,'Food Database'!B:B)*B8,"") -> 30 | E8: =IFERROR(_xlfn.XLOOKUP(A8,'Food Database'!A:A,'Food Database'!C:C)*B8,"") -> 1
A9: Usta Dönerci Fit Bi Kase | B9: 1 | C9: 46220 | D9: =IFERROR(_xlfn.XLOOKUP(A9,'Food Database'!A:A,'Food Database'!B:B)*B9,"") -> 630 | E9: =IFERROR(_xlfn.XLOOKUP(A9,'Food Database'!A:A,'Food Database'!C:C)*B9,"") -> 46
A10: Starbucks Grande Iced Protein Latte | B10: 1 | C10: 46220 | D10: =IFERROR(_xlfn.XLOOKUP(A10,'Food Database'!A:A,'Food Database'!B:B)*B10,"") -> 123 | E10: =IFERROR(_xlfn.XLOOKUP(A10,'Food Database'!A:A,'Food Database'!C:C)*B10,"") -> 21
A11: Şekersiz Probis(tane) | B11: 2 | C11: 46220 | D11: =IFERROR(_xlfn.XLOOKUP(A11,'Food Database'!A:A,'Food Database'!B:B)*B11,"") -> 122 | E11: =IFERROR(_xlfn.XLOOKUP(A11,'Food Database'!A:A,'Food Database'!C:C)*B11,"") -> 4.6
A12: Büyük Salatalık | B12: 1 | C12: 46221 | D12: =IFERROR(_xlfn.XLOOKUP(A12,'Food Database'!A:A,'Food Database'!B:B)*B12,"") -> 30 | E12: =IFERROR(_xlfn.XLOOKUP(A12,'Food Database'!A:A,'Food Database'!C:C)*B12,"") -> 1
A13: Şekersiz Probis(tane) | B13: 2 | C13: 46221 | D13: =IFERROR(_xlfn.XLOOKUP(A13,'Food Database'!A:A,'Food Database'!B:B)*B13,"") -> 122 | E13: =IFERROR(_xlfn.XLOOKUP(A13,'Food Database'!A:A,'Food Database'!C:C)*B13,"") -> 4.6
A14: Subway Double Fileto(15 cm) | B14: 1 | C14: 46221 | D14: =IFERROR(_xlfn.XLOOKUP(A14,'Food Database'!A:A,'Food Database'!B:B)*B14,"") -> 550 | E14: =IFERROR(_xlfn.XLOOKUP(A14,'Food Database'!A:A,'Food Database'!C:C)*B14,"") -> 47
A15: Büyük Domates | B15: 1 | C15: 46222 | D15: =IFERROR(_xlfn.XLOOKUP(A15,'Food Database'!A:A,'Food Database'!B:B)*B15,"") -> 30 | E15: =IFERROR(_xlfn.XLOOKUP(A15,'Food Database'!A:A,'Food Database'!C:C)*B15,"") -> 1.5
A16: Bahs Protein Bar | B16: 1 | C16: 46222 | D16: =IFERROR(_xlfn.XLOOKUP(A16,'Food Database'!A:A,'Food Database'!B:B)*B16,"") -> 150 | E16: =IFERROR(_xlfn.XLOOKUP(A16,'Food Database'!A:A,'Food Database'!C:C)*B16,"") -> 15
A17: Subway Double Fileto(15 cm) | B17: 1 | C17: 46222 | D17: =IFERROR(_xlfn.XLOOKUP(A17,'Food Database'!A:A,'Food Database'!B:B)*B17,"") -> 550 | E17: =IFERROR(_xlfn.XLOOKUP(A17,'Food Database'!A:A,'Food Database'!C:C)*B17,"") -> 47
... A19: Bahs Protein Bar | B19: 0.5 | C19: 46222 | D19: =IFERROR(_xlfn.XLOOKUP(A19,'Food Database'!A:A,'Food Database'!B:B)*B19,"") -> 75 | E19: =IFERROR(_xlfn.XLOOKUP(A19,'Food Database'!A:A,'Food Database'!C:C)*B19,"") -> 7.5
A20: Tavuklu Çoban Salata | B20: N/A | C20: 46222 | D20: 120 | E20: 14.5
A21: Yoğurtlu Mantı | B21: N/A | C21: 46223 | D21: 210 | E21: 11
A22: Bahs Protein Bar | B22: 1 | C22: 46223 | D22: =IFERROR(_xlfn.XLOOKUP(A22,'Food Database'!A:A,'Food Database'!B:B)*B22,"") -> 150 | E22: =IFERROR(_xlfn.XLOOKUP(A22,'Food Database'!A:A,'Food Database'!C:C)*B22,"") -> 15
A23: İçim Fit Kakaolu Süt | B23: 0.45 | C23: 46223 | D23: =IFERROR(_xlfn.XLOOKUP(A23,'Food Database'!A:A,'Food Database'!B:B)*B23,"") -> 84.6 | E23: =IFERROR(_xlfn.XLOOKUP(A23,'Food Database'!A:A,'Food Database'!C:C)*B23,"") -> 11.7
A24: Tavuklu Yoğurtlu Çoban Salata | B24: N/A | C24: 46223 | D24: 280 | E24: 42.3
A25: Tavuklu Yoğurtlu Çoban Salata | B25: N/A | C25: 46224 | D25: 90 | E25: 14
A26: Bahs Protein Bar | B26: 0.5 | C26: 46224 | D26: =IFERROR(_xlfn.XLOOKUP(A26,'Food Database'!A:A,'Food Database'!B:B)*B26,"") -> 75 | E26: =IFERROR(_xlfn.XLOOKUP(A26,'Food Database'!A:A,'Food Database'!C:C)*B26,"") -> 7.5
A27: Bahs Protein Bar | B27: 1 | C27: 46224 | D27: =IFERROR(_xlfn.XLOOKUP(A27,'Food Database'!A:A,'Food Database'!B:B)*B27,"") -> 150 | E27: =IFERROR(_xlfn.XLOOKUP(A27,'Food Database'!A:A,'Food Database'!C:C)*B27,"") -> 15
A28: Bahs Protein Bar | B28: 1 | C28: 46224 | D28: =IFERROR(_xlfn.XLOOKUP(A28,'Food Database'!A:A,'Food Database'!B:B)*B28,"") -> 150 | E28: =IFERROR(_xlfn.XLOOKUP(A28,'Food Database'!A:A,'Food Database'!C:C)*B28,"") -> 15
A29: Monster Watermelon | B29: 1 | C29: 46224 | D29: =IFERROR(_xlfn.XLOOKUP(A29,'Food Database'!A:A,'Food Database'!B:B)*B29,"") -> 50 | E29: =IFERROR(_xlfn.XLOOKUP(A29,'Food Database'!A:A,'Food Database'!C:C)*B29,"") -> 0
A30: Yoğurtlu Tavuk+Brokoli | B30: N/A | C30: 46224 | D30: 400 | E30: 65
A31: Bahs Protein Bar | B31: 1 | C31: 46225 | D31: =IFERROR(_xlfn.XLOOKUP(A31,'Food Database'!A:A,'Food Database'!B:B)*B31,"") -> 150 | E31: =IFERROR(_xlfn.XLOOKUP(A31,'Food Database'!A:A,'Food Database'!C:C)*B31,"") -> 15
A32: Yoğurtlu Tavuk+Brokoli | B32: N/A | C32: 46225 | D32: 400 | E32: 65
A33: Monster Watermelon | B33: 1 | C33: 46225 | D33: =IFERROR(_xlfn.XLOOKUP(A33,'Food Database'!A:A,'Food Database'!B:B)*B33,"") -> 50 | E33: =IFERROR(_xlfn.XLOOKUP(A33,'Food Database'!A:A,'Food Database'!C:C)*B33,"") -> 0
A34: Yoğurtlu Brokoli | B34: N/A | C34: 46225 | D34: 100 | E34: 7.5
A35: Bahs Protein Bar | B35: 1 | C35: 46226 | D35: =IFERROR(_xlfn.XLOOKUP(A35,'Food Database'!A:A,'Food Database'!B:B)*B35,"") -> 150 | E35: =IFERROR(_xlfn.XLOOKUP(A35,'Food Database'!A:A,'Food Database'!C:C)*B35,"") -> 15
A36: Bahs Protein Bar | B36: 1 | C36: 46226 | D36: =IFERROR(_xlfn.XLOOKUP(A36,'Food Database'!A:A,'Food Database'!B:B)*B36,"") -> 150 | E36: =IFERROR(_xlfn.XLOOKUP(A36,'Food Database'!A:A,'Food Database'!C:C)*B36,"") -> 15
A37: Arbys Beefn Cheddar | B37: 1 | C37: 46226 | D37: =IFERROR(_xlfn.XLOOKUP(A37,'Food Database'!A:A,'Food Database'!B:B)*B37,"") -> 520 | E37: =IFERROR(_xlfn.XLOOKUP(A37,'Food Database'!A:A,'Food Database'!C:C)*B37,"") -> 32
A38: Pınar 52g Süt | B38: 0.4 | C38: 46226 | D38: =IFERROR(_xlfn.XLOOKUP(A38,'Food Database'!A:A,'Food Database'!B:B)*B38,"") -> 132 | E38: =IFERROR(_xlfn.XLOOKUP(A38,'Food Database'!A:A,'Food Database'!C:C)*B38,"") -> 20.8
A39: Arbys Chicken Tenders | B39: 5 | C39: 46226 | D39: =IFERROR(_xlfn.XLOOKUP(A39,'Food Database'!A:A,'Food Database'!B:B)*B39,"") -> 270 | E39: =IFERROR(_xlfn.XLOOKUP(A39,'Food Database'!A:A,'Food Database'!C:C)*B39,"") -> 13.5
A40: Bahs Protein Bar | B40: 1 | C40: 46227 | D40: =IFERROR(_xlfn.XLOOKUP(A40,'Food Database'!A:A,'Food Database'!B:B)*B40,"") -> 150 | E40: =IFERROR(_xlfn.XLOOKUP(A40,'Food Database'!A:A,'Food Database'!C:C)*B40,"") -> 15
A41: Pınar 52g Süt | B41: 0.56 | C41: 46227 | D41: =IFERROR(_xlfn.XLOOKUP(A41,'Food Database'!A:A,'Food Database'!B:B)*B41,"") -> 184.8 | E41: =IFERROR(_xlfn.XLOOKUP(A41,'Food Database'!A:A,'Food Database'!C:C)*B41,"") -> 29.12
...

Sheet Exercise
A1: Date | B1: Source | C1: Kcal
A2: 46218 | B2: Yürüyüş | C2: 466
A3: 46219 | B3: Yürüyüş | C3: 26
A4: 46220 | B4: Yürüyüş | C4: 250
A5: 46221 | B5: Yürüyüş | C5: 25
A6: 46222 | B6: Yürüyüş | C6: 160
A7: 46223 | B7: Yürüyüş | C7: 87
A8: 46224 | B8: Yürüyüş | C8: 50
A9: 46225 | B9: Yürüyüş | C9: 350
A10: 46226 | B10: Yürüyüş | C10: 60
A11: 46227 | B11: Yürüyüş | C11: 250
A12: 46228 | B12: Yürüyüş | C12: 300

Sheet Food Database
A1: Food | B1: Kcal | C1: Protein
A2: Starbucks Grande Iced Protein Latte | B2: 123 | C2: 21
A3: Subway Single Fileto(15cm) | B3: 400 | C3: 25.6
A4: Subway Winterberry Cookie | B4: 200 | C4: 2
A5: Subway Double Fileto(15 cm) | B5: 550 | C5: 47
A6: Büyük Salatalık | B6: 30 | C6: 1
A7: Usta Dönerci Fit Bi Kase | B7: 630 | C7: 46
A8: Şekersiz Probis(tane) | B8: 61 | C8: 2.3
A9: Büyük Domates | B9: 30 | C9: 1.5
A10: Bahs Protein Bar | B10: 150 | C10: 15
A11: Kremalı Mantar Çabuk Çorba | B11: 80 | C11: 2
A12: Tavuk Kanat | B12: 90 | C12: 7.5
A13: İçim Fit Kakaolu Süt | B13: 188 | C13: 26
... A18: Pınar 26g Süt | B18: 250 | C18: 26

Sheet Dashboard
A1: Date | B1: Total Cal | C1: Total Protein | D1: Deficit/Surplus | E1: Total Deficit | F1: Completion Percentage | G1: Daily Average Deficit | J1: BMR
A2: 46218 | B2: =SUMIFS('Food Log'!D:D,'Food Log'!C:C,A2) -> 923 | C2: =SUMIFS('Food Log'!E:E,'Food Log'!C:C,A2) -> 72.2 | D2: =SUMIFS('Food Log'!D:D,'Food Log'!C:C,A2)-($J$2+_xlfn.XLOOKUP(A2,Exercise!A:A,Exercise!C:C,0)) -> -1163 | E2: =GETPIVOTDATA("Sum of Deficit/Surplus",'DB PivotTable'!$A$3) -> -10222.6 | F2: =ABS(E2)/154000 -> 0.066380519 | G2: =AVERAGE(D2:D1000) -> -929.32727 | J2: 1620
A3: 46219 | B3: =SUMIFS('Food Log'!D:D,'Food Log'!C:C,A3) -> 990 | C3: =SUMIFS('Food Log'!E:E,'Food Log'!C:C,A3) -> 79 | D3: =SUMIFS('Food Log'!D:D,'Food Log'!C:C,A3)-($J$2+_xlfn.XLOOKUP(A3,Exercise!A:A,Exercise!C:C,0)) -> -656
A4: 46220 | B4: =SUMIFS('Food Log'!D:D,'Food Log'!C:C,A4) -> 905 | C4: =SUMIFS('Food Log'!E:E,'Food Log'!C:C,A4) -> 72.6 | D4: =SUMIFS('Food Log'!D:D,'Food Log'!C:C,A4)-($J$2+_xlfn.XLOOKUP(A4,Exercise!A:A,Exercise!C:C,0)) -> -965
A5: 46221 | B5: =SUMIFS('Food Log'!D:D,'Food Log'!C:C,A5) -> 702 | C5: =SUMIFS('Food Log'!E:E,'Food Log'!C:C,A5) -> 52.6 | D5: =SUMIFS('Food Log'!D:D,'Food Log'!C:C,A5)-($J$2+_xlfn.XLOOKUP(A5,Exercise!A:A,Exercise!C:C,0)) -> -943
A6: 46222 | B6: =SUMIFS('Food Log'!D:D,'Food Log'!C:C,A6) -> 1005 | C6: =SUMIFS('Food Log'!E:E,'Food Log'!C:C,A6) -> 87.5 | D6: =SUMIFS('Food Log'!D:D,'Food Log'!C:C,A6)-($J$2+_xlfn.XLOOKUP(A6,Exercise!A:A,Exercise!C:C,0)) -> -775
A7: 46223 | B7: =SUMIFS('Food Log'!D:D,'Food Log'!C:C,A7) -> 724.6 | C7: =SUMIFS('Food Log'!E:E,'Food Log'!C:C,A7) -> 80 | D7: =SUMIFS('Food Log'!D:D,'Food Log'!C:C,A7)-($J$2+_xlfn.XLOOKUP(A7,Exercise!A:A,Exercise!C:C,0)) -> -982.4
A8: 46224 | B8: =SUMIFS('Food Log'!D:D,'Food Log'!C:C,A8) -> 915 | C8: =SUMIFS('Food Log'!E:E,'Food Log'!C:C,A8) -> 116.5 | D8: =SUMIFS('Food Log'!D:D,'Food Log'!C:C,A8)-($J$2+_xlfn.XLOOKUP(A8,Exercise!A:A,Exercise!C:C,0)) -> -755
A9: 46225 | B9: =SUMIFS('Food Log'!D:D,'Food Log'!C:C,A9) -> 700 | C9: =SUMIFS('Food Log'!E:E,'Food Log'!C:C,A9) -> 87.5 | D9: =SUMIFS('Food Log'!D:D,'Food Log'!C:C,A9)-($J$2+_xlfn.XLOOKUP(A9,Exercise!A:A,Exercise!C:C,0)) -> -1270
A10: 46226 | B10: =SUMIFS('Food Log'!D:D,'Food Log'!C:C,A10) -> 1222 | C10: =SUMIFS('Food Log'!E:E,'Food Log'!C:C,A10) -> 96.3 | D10: =SUMIFS('Food Log'!D:D,'Food Log'!C:C,A10)-($J$2+_xlfn.XLOOKUP(A10,Exercise!A:A,Exercise!C:C,0)) -> -458
A11: 46227 | B11: =SUMIFS('Food Log'!D:D,'Food Log'!C:C,A11) -> 954.8 | C11: =SUMIFS('Food Log'!E:E,'Food Log'!C:C,A11) -> 99.12 | D11: =SUMIFS('Food Log'!D:D,'Food Log'!C:C,A11)-($J$2+_xlfn.XLOOKUP(A11,Exercise!A:A,Exercise!C:C,0)) -> -915.2
A12: 46228 | B12: =SUMIFS('Food Log'!D:D,'Food Log'!C:C,A12) -> 580 | C12: =SUMIFS('Food Log'!E:E,'Food Log'!C:C,A12) -> 61.92 | D12: =SUMIFS('Food Log'!D:D,'Food Log'!C:C,A12)-($J$2+_xlfn.XLOOKUP(A12,Exercise!A:A,Exercise!C:C,0)) -> -1340

Sheet DB PivotTable
A3: Row Labels | B3: Sum of Deficit/Surplus | C3: Sum of Total Cal | D3: Sum of Total Protein
A4: 46218 | B4: -1163 | C4: 923 | D4: 72.2
A5: 46219 | B5: -656 | C5: 990 | D5: 79
A6: 46220 | B6: -965 | C6: 905 | D6: 72.6
A7: 46221 | B7: -943 | C7: 702 | D7: 52.6
A8: 46222 | B8: -775 | C8: 1005 | D8: 87.5
A9: (blank)
A10: 46223 | B10: -982.4 | C10: 724.6 | D10: 80
A11: 46224 | B11: -755 | C11: 915 | D11: 116.5
A12: 46225 | B12: -1270 | C12: 700 | D12: 87.5
A13: 46226 | B13: -458 | C13: 1222 | D13: 96.3
A14: 46227 | B14: -915.2 | C14: 954.8 | D14: 99.12
A15: 46228 | B15: -1340 | C15: 580 | D15: 61.92
A16: Grand Total | B16: -10222.6 | C16: 9621.4 | D16: 905.24
